16. What is the output of following codes:

--->
def foo():
    try:
        return 1
    finally:
        return 2
k = foo()
print(k)

---Output:
2


---->
def a():
    try:
        f(x, 4)
    finally:
        print('after f')
        print('after f?')
a()

---Outpt:
It gives error: "name 'f' is not defined"
(Because try/except/finally handles only runtime errors not the syntax/compile errors)